<?xml version="1.0" encoding="UTF-8"?>
<testng-results ignored="0" total="5" passed="3" failed="2" skipped="0">
  <reporter-output>
  </reporter-output>
  <suite started-at="2025-01-19T22:41:15 IST" name="Suite_1" finished-at="2025-01-19T22:41:25 IST" duration-ms="10056">
    <groups>
    </groups>
    <test started-at="2025-01-19T22:41:15 IST" name="Test3" finished-at="2025-01-19T22:41:25 IST" duration-ms="10056">
      <class name="com.soni.JKP1008.TestClass_3">
        <test-method signature="test1()[pri:0, instance:com.soni.JKP1008.TestClass_3@384ad17b]" started-at="2025-01-19T22:41:15 IST" name="test1" finished-at="2025-01-19T22:41:15 IST" duration-ms="18" status="FAIL">
          <exception class="java.lang.AssertionError">
            <message>
              <![CDATA[expected [false] but found [true]]]>
            </message>
            <full-stacktrace>
              <![CDATA[java.lang.AssertionError: expected [false] but found [true]
at org.testng.Assert.fail(Assert.java:99)
at org.testng.Assert.failNotEquals(Assert.java:1037)
at org.testng.Assert.assertEqualsImpl(Assert.java:140)
at org.testng.Assert.assertEquals(Assert.java:122)
at org.testng.Assert.assertEquals(Assert.java:819)
at org.testng.Assert.assertEquals(Assert.java:829)
at com.soni.JKP1008.TestClass_3.test1(TestClass_3.java:14)
at java.base/jdk.internal.reflect.DirectMethodHandleAccessor.invoke(DirectMethodHandleAccessor.java:103)
at java.base/java.lang.reflect.Method.invoke(Method.java:580)
at org.testng.internal.MethodInvocationHelper.invokeMethod(MethodInvocationHelper.java:133)
at org.testng.internal.TestInvoker.invokeMethod(TestInvoker.java:598)
at org.testng.internal.TestInvoker.invokeTestMethod(TestInvoker.java:173)
at org.testng.internal.MethodRunner.runInSequence(MethodRunner.java:46)
at org.testng.internal.TestInvoker$MethodInvocationAgent.invoke(TestInvoker.java:824)
at org.testng.internal.TestInvoker.invokeTestMethods(TestInvoker.java:146)
at org.testng.internal.TestMethodWorker.invokeTestMethods(TestMethodWorker.java:146)
at org.testng.internal.TestMethodWorker.run(TestMethodWorker.java:128)
at java.base/java.util.concurrent.ThreadPoolExecutor.runWorker(ThreadPoolExecutor.java:1144)
at java.base/java.util.concurrent.ThreadPoolExecutor$Worker.run(ThreadPoolExecutor.java:642)
at java.base/java.lang.Thread.run(Thread.java:1575)
]]>
            </full-stacktrace>
          </exception> <!-- java.lang.AssertionError -->
          <reporter-output>
          </reporter-output>
        </test-method> <!-- test1 -->
        <test-method signature="test2()[pri:0, instance:com.soni.JKP1008.TestClass_3@384ad17b]" started-at="2025-01-19T22:41:15 IST" name="test2" finished-at="2025-01-19T22:41:25 IST" duration-ms="10027" status="PASS">
          <reporter-output>
          </reporter-output>
        </test-method> <!-- test2 -->
        <test-method signature="test3()[pri:0, instance:com.soni.JKP1008.TestClass_3@384ad17b]" started-at="2025-01-19T22:41:15 IST" name="test3" finished-at="2025-01-19T22:41:25 IST" duration-ms="10027" status="PASS">
          <reporter-output>
          </reporter-output>
        </test-method> <!-- test3 -->
      </class> <!-- com.soni.JKP1008.TestClass_3 -->
    </test> <!-- Test3 -->
  </suite> <!-- Suite_1 -->
  <suite started-at="2025-01-19T22:41:25 IST" name="Suite_1 (0)" finished-at="2025-01-19T22:41:35 IST" duration-ms="10025">
    <groups>
    </groups>
    <test started-at="2025-01-19T22:41:25 IST" name="Test1" finished-at="2025-01-19T22:41:35 IST" duration-ms="10025">
      <class name="com.soni.JKP1008.TestClass_2">
        <test-method signature="test1()[pri:0, instance:com.soni.JKP1008.TestClass_2@77847718]" started-at="2025-01-19T22:41:25 IST" name="test1" finished-at="2025-01-19T22:41:25 IST" duration-ms="1" status="FAIL">
          <exception class="java.lang.AssertionError">
            <message>
              <![CDATA[expected [false] but found [true]]]>
            </message>
            <full-stacktrace>
              <![CDATA[java.lang.AssertionError: expected [false] but found [true]
at org.testng.Assert.fail(Assert.java:99)
at org.testng.Assert.failNotEquals(Assert.java:1037)
at org.testng.Assert.assertEqualsImpl(Assert.java:140)
at org.testng.Assert.assertEquals(Assert.java:122)
at org.testng.Assert.assertEquals(Assert.java:819)
at org.testng.Assert.assertEquals(Assert.java:829)
at com.soni.JKP1008.TestClass_2.test1(TestClass_2.java:13)
at java.base/jdk.internal.reflect.DirectMethodHandleAccessor.invoke(DirectMethodHandleAccessor.java:103)
at java.base/java.lang.reflect.Method.invoke(Method.java:580)
at org.testng.internal.MethodInvocationHelper.invokeMethod(MethodInvocationHelper.java:133)
at org.testng.internal.TestInvoker.invokeMethod(TestInvoker.java:598)
at org.testng.internal.TestInvoker.invokeTestMethod(TestInvoker.java:173)
at org.testng.internal.MethodRunner.runInSequence(MethodRunner.java:46)
at org.testng.internal.TestInvoker$MethodInvocationAgent.invoke(TestInvoker.java:824)
at org.testng.internal.TestInvoker.invokeTestMethods(TestInvoker.java:146)
at org.testng.internal.TestMethodWorker.invokeTestMethods(TestMethodWorker.java:146)
at org.testng.internal.TestMethodWorker.run(TestMethodWorker.java:128)
at java.base/java.util.ArrayList.forEach(ArrayList.java:1597)
at org.testng.TestRunner.privateRun(TestRunner.java:794)
at org.testng.TestRunner.run(TestRunner.java:596)
at org.testng.SuiteRunner.runTest(SuiteRunner.java:377)
at org.testng.SuiteRunner.runSequentially(SuiteRunner.java:371)
at org.testng.SuiteRunner.privateRun(SuiteRunner.java:332)
at org.testng.SuiteRunner.run(SuiteRunner.java:276)
at org.testng.SuiteRunnerWorker.runSuite(SuiteRunnerWorker.java:53)
at org.testng.SuiteRunnerWorker.run(SuiteRunnerWorker.java:96)
at org.testng.TestNG.runSuitesSequentially(TestNG.java:1212)
at org.testng.TestNG.runSuitesSequentially(TestNG.java:1207)
at org.testng.TestNG.runSuitesLocally(TestNG.java:1134)
at org.testng.TestNG.runSuites(TestNG.java:1063)
at org.testng.TestNG.run(TestNG.java:1031)
at org.testng.remote.AbstractRemoteTestNG.run(AbstractRemoteTestNG.java:115)
at org.testng.remote.RemoteTestNG.initAndRun(RemoteTestNG.java:293)
at org.testng.remote.RemoteTestNG.main(RemoteTestNG.java:91)
]]>
            </full-stacktrace>
          </exception> <!-- java.lang.AssertionError -->
          <reporter-output>
          </reporter-output>
        </test-method> <!-- test1 -->
        <test-method signature="test2()[pri:0, instance:com.soni.JKP1008.TestClass_2@77847718]" started-at="2025-01-19T22:41:25 IST" name="test2" finished-at="2025-01-19T22:41:35 IST" duration-ms="10015" status="PASS">
          <reporter-output>
          </reporter-output>
        </test-method> <!-- test2 -->
      </class> <!-- com.soni.JKP1008.TestClass_2 -->
    </test> <!-- Test1 -->
  </suite> <!-- Suite_1 (0) -->
  <suite started-at="2025-01-19T22:41:35 IST" name="Suite_with_multiple_testng" finished-at="2025-01-19T22:41:35 IST" duration-ms="0">
    <groups>
    </groups>
  </suite> <!-- Suite_with_multiple_testng -->
</testng-results>
